<?xml version="1.0" ?>
<!-- =================================================================================== -->
<!-- |    This document was autogenerated by xacro from robot.urdf.xacro               | -->
<!-- |    EDITING THIS FILE BY HAND IS NOT RECOMMENDED                                 | -->
<!-- =================================================================================== -->
<robot name="robot">
  <material name="body">
    <color rgba="0.1 0.1 0.1 1"/>
  </material>
  <material name="bed">
    <color rgba="0.1 0.1 0.1 1"/>
  </material>
  <material name="chassis">
    <color rgba="0.1 0.1 0.1 1"/>
  </material>
  <material name="wheel">
    <color rgba="0.1 0.1 0.1 1"/>
  </material>
  <link name="base_link"/>
  <!-- Body -->
  <joint name="body_joint" type="fixed">
    <parent link="base_link"/>
    <child link="body_link"/>
    <origin xyz="0 0 0.14765"/>
  </joint>
  <link name="body_link">
    <!-- <visual>
            <geometry>
            </geometry>
            <material name="body"/>
        </visual> -->
    <visual>
      <geometry>
        <box size="0.472 0.12 0.083"/>
      </geometry>
      <material name="body"/>
    </visual>
    <collision>
      <geometry>
        <box size="0.472 0.12 0.083"/>
      </geometry>
    </collision>
  </link>
  <!-- Bed -->
  <joint name="bed_joint" type="fixed">
    <parent link="body_link"/>
    <child link="bed_link"/>
    <origin xyz="-0.08200000000000002 0 0.0965"/>
  </joint>
  <link name="bed_link">
    <!-- <visual>
            <origin xyz="" rpy="${pi} 0 0"/>
            <geometry>
                <mesh filename="../meshes/bed2.stl"/>
            </geometry>
            <material name="bed"/>
        </visual> -->
    <visual>
      <geometry>
        <box size="0.52 0.27 0.11"/>
      </geometry>
      <material name="bed"/>
    </visual>
    <collision>
      <geometry>
        <box size="0.52 0.27 0.11"/>
      </geometry>
    </collision>
  </link>
  <!-- Chassis -->
  <joint name="front_steering_joint" type="revolute">
    <parent link="body_link"/>
    <child link="front_steering_link"/>
    <origin rpy="1.5707963267948966 0 0" xyz="0.0721 0 -0.07465000000000001"/>
    <axis xyz="0 -1 0"/>
    <limit effort="1" lower="-0.3490658503988659" upper="0.3490658503988659" velocity="1"/>
  </joint>
  <link name="front_steering_link">
    <!-- <visual>
            <geometry></geometry>
            <material name="steering"/>
        </visual> -->
    <visual>
      <geometry>
        <cylinder length="0.225" radius="0.02"/>
      </geometry>
      <material name="steering"/>
    </visual>
    <visual>
      <origin rpy="-1.5707963267948966 0 0" xyz="0 0.016575 0"/>
      <geometry>
        <cylinder length="0.03315" radius="0.0115"/>
      </geometry>
      <material name="steering"/>
    </visual>
    <collision>
      <geometry>
        <cylinder length="0.225" radius="0.02"/>
      </geometry>
    </collision>
    <collision>
      <origin rpy="-1.5707963267948966 0 0" xyz="0 0.016575 0"/>
      <geometry>
        <cylinder length="0.03315" radius="0.0115"/>
      </geometry>
    </collision>
  </link>
  <joint name="rear_steering_joint" type="revolute">
    <parent link="body_link"/>
    <child link="rear_steering_link"/>
    <origin rpy="1.5707963267948966 0 0" xyz="-0.19111999999999998 0 -0.07465000000000001"/>
    <axis xyz="0 -1 0"/>
    <limit effort="1" lower="-0.3490658503988659" upper="0.3490658503988659" velocity="1"/>
  </joint>
  <link name="rear_steering_link">
    <!-- <visual>
            <geometry></geometry>
            <material name="steering"/>
        </visual> -->
    <visual>
      <geometry>
        <cylinder length="0.225" radius="0.02"/>
      </geometry>
      <material name="steering"/>
    </visual>
    <visual>
      <origin rpy="-1.5707963267948966 0 0" xyz="0 0.016575 0"/>
      <geometry>
        <cylinder length="0.03315" radius="0.0115"/>
      </geometry>
      <material name="steering"/>
    </visual>
    <collision>
      <geometry>
        <cylinder length="0.225" radius="0.02"/>
      </geometry>
    </collision>
    <collision>
      <origin rpy="-1.5707963267948966 0 0" xyz="0 0.016575 0"/>
      <geometry>
        <cylinder length="0.03315" radius="0.0115"/>
      </geometry>
    </collision>
  </link>
  <!-- Wheels -->
  <joint name="front_left_wheel_joint" type="continuous">
    <parent link="front_steering_link"/>
    <child link="front_left_wheel_link"/>
    <origin rpy="-3.141592653589793 0 0" xyz="0 0 -0.135605"/>
    <axis xyz="0 0 1"/>
  </joint>
  <link name="front_left_wheel_link">
    <!-- <visual>
            <geometry></geometry>
            <material name="wheel"/>
        </visual> -->
    <visual>
      <geometry>
        <cylinder length="0.04621" radius="0.073"/>
      </geometry>
      <material name="wheel"/>
    </visual>
    <collision>
      <geometry>
        <cylinder length="0.04621" radius="0.073"/>
      </geometry>
    </collision>
  </link>
  <joint name="front_right_wheel_joint" type="continuous">
    <parent link="front_steering_link"/>
    <child link="front_right_wheel_link"/>
    <origin xyz="0 0 0.135605"/>
    <axis xyz="0 0 -1"/>
  </joint>
  <link name="front_right_wheel_link">
    <!-- <visual>
            <geometry></geometry>
            <material name="wheel"/>
        </visual> -->
    <visual>
      <geometry>
        <cylinder length="0.04621" radius="0.073"/>
      </geometry>
      <material name="wheel"/>
    </visual>
    <collision>
      <geometry>
        <cylinder length="0.04621" radius="0.073"/>
      </geometry>
    </collision>
  </link>
  <joint name="rear_left_wheel_joint" type="continuous">
    <parent link="rear_steering_link"/>
    <child link="rear_left_wheel_link"/>
    <origin rpy="-3.141592653589793 0 0" xyz="0 0 -0.135605"/>
    <axis xyz="0 0 1"/>
  </joint>
  <link name="rear_left_wheel_link">
    <!-- <visual>
            <geometry></geometry>
            <material name="wheel"/>
        </visual> -->
    <visual>
      <geometry>
        <cylinder length="0.04621" radius="0.073"/>
      </geometry>
      <material name="wheel"/>
    </visual>
    <collision>
      <geometry>
        <cylinder length="0.04621" radius="0.073"/>
      </geometry>
    </collision>
  </link>
  <joint name="rear_right_wheel_joint" type="continuous">
    <parent link="rear_steering_link"/>
    <child link="rear_right_wheel_link"/>
    <origin xyz="0 0 0.135605"/>
    <axis xyz="0 0 -1"/>
  </joint>
  <link name="rear_right_wheel_link">
    <!-- <visual>
            <geometry></geometry>
            <material name="wheel"/>
        </visual> -->
    <visual>
      <geometry>
        <cylinder length="0.04621" radius="0.073"/>
      </geometry>
      <material name="wheel"/>
    </visual>
    <collision>
      <geometry>
        <cylinder length="0.04621" radius="0.073"/>
      </geometry>
    </collision>
  </link>
  <!-- <xacro:include filename="lidar.xacro" /> -->
  <!-- <xacro:include filename="cameras.xacro"/> -->
</robot>
